Workbook

Sheet GFS Entry
A1: Ledger* | B1: Amount Class* | C1: Entity* | D1: Account Sub - Account* | E1: Center* | F1: Office Location* | G1: Product Sub - Product* | H1: Affiliate* | I1: Txn ccy | J1: Trans Amount | K1: Func ccy | L1: Func Amount | M1: Rep ccy | N1: Rep Amount | O1: FX Rate (TXN2FUNC) | P1: FX Rate (TXN2REP) | Q1: SL Journal Line Description | R1: Statistical Amount | S1: Block-of-Business | T1: Client | U1: Reinsurer | V1: Risk Location | W1: Obligor | X1: Accident Year | Y1: Agreement | Z1: Catastrophe Loss Indicator | AA1: Catastrophe Code | AB1: Marketing Channel | AC1: Program Code | AD1: Pay Code | AE1: Code Type | AF1: Covered Equipment | AG1: Underwriting Year | AH1: Dealer Group Number | AI1: Dealer Number | AJ1: Dealer State | AK1: Insured State | AL1: Policy Number
A2: USD Functional | B2: Cash | C2: E01300 | D2: A700018-00 | E2: C200593 | F2: L0001 | G2: P0000-000 | H2: E00000 | I2: USD | J2: =-Allocation!I10 -> -8646841.1 | Q2: Spread Group Ins. By FTE 10/2025
A3: USD Functional | B3: Cash | C3: E01300 | D3: A700018-00 | E3: C200593 | F3: L0001 | G3: P0000-000 | H3: E00330 | I3: USD | J3: =-Allocation!I9 -> -28628.794 | Q3: Spread Group Ins. By FTE 10/2025
A4: USD Functional | B4: Cash | C4: E00330 | D4: A700018-00 | E4: C040414 | F4: L0001 | G4: P0000-000 | H4: E01300 | I4: USD | J4: 285.1456 | Q4: Spread Group Ins. By FTE 10/2025
A5: USD Functional | B5: Cash | C5: E01300 | D5: A700018-00 | E5: C010000 | F5: L0001 | G5: P0000-000 | H5: E00000 | I5: USD | J5: 5520.6774 | Q5: Spread Group Ins. By FTE 10/2025
A6: USD Functional | B6: Cash | C6: E01300 | D6: A700018-00 | E6: C010011 | F6: L0001 | G6: P0000-000 | H6: E00000 | I6: USD | J6: 802.96389 | Q6: Spread Group Ins. By FTE 10/2025
A7: USD Functional | B7: Cash | C7: E01300 | D7: A700018-00 | E7: C010101 | F7: L0001 | G7: P0000-000 | H7: E00000 | I7: USD | J7: 10477.008 | Q7: Spread Group Ins. By FTE 10/2025
A8: USD Functional | B8: Cash | C8: E01300 | D8: A700018-00 | E8: C010105 | F8: L0001 | G8: P0000-000 | H8: E00000 | I8: USD | J8: 8264.6339 | Q8: Spread Group Ins. By FTE 10/2025
A9: USD Functional | B9: Cash | C9: E01300 | D9: A700018-00 | E9: C010110 | F9: L0001 | G9: P0000-000 | H9: E00000 | I9: USD | J9: 2712.9732 | Q9: Spread Group Ins. By FTE 10/2025
A10: USD Functional | B10: Cash | C10: E01300 | D10: A700018-00 | E10: C010111 | F10: L0001 | G10: P0000-000 | H10: E00000 | I10: USD | J10: 5686.7714 | Q10: Spread Group Ins. By FTE 10/2025
A11: USD Functional | B11: Cash | C11: E01300 | D11: A700018-00 | E11: C010115 | F11: L0001 | G11: P0000-000 | H11: E00000 | I11: USD | J11: 5762.7926 | Q11: Spread Group Ins. By FTE 10/2025
A12: USD Functional | B12: Cash | C12: E01300 | D12: A700018-00 | E12: C010121 | F12: L0001 | G12: P0000-000 | H12: E00000 | I12: USD | J12: 4818.8518 | Q12: Spread Group Ins. By FTE 10/2025
A13: USD Functional | B13: Cash | C13: E01300 | D13: A700018-00 | E13: C010122 | F13: L0001 | G13: P0000-000 | H13: E00000 | I13: USD | J13: 16824.506 | Q13: Spread Group Ins. By FTE 10/2025
A14: USD Functional | B14: Cash | C14: E01300 | D14: A700018-00 | E14: C010124 | F14: L0001 | G14: P0000-000 | H14: E00000 | I14: USD | J14: 6416.1809 | Q14: Spread Group Ins. By FTE 10/2025
A15: USD Functional | B15: Cash | C15: E01300 | D15: A700018-00 | E15: C010127 | F15: L0001 | G15: P0000-000 | H15: E00000 | I15: USD | J15: 6279.5458 | Q15: Spread Group Ins. By FTE 10/2025
... A709: USD Functional | B709: Cash | C709: E01300 | D709: A700018-00 | E709: C515008 | F709: L0001 | G709: P0000-000 | H709: E00000 | I709: USD | J709: 1054.8229 | Q709: Spread Group Ins. By FTE 10/2025

Sheet Allocation
C3: Entity | D3: Cost Center | E3: Amount
C4: E00330 | D4: C040414 | E4: 285.1456
C5: E01300 | D5: C010000 | E5: 5520.6774
C6: E01300 | D6: C010011 | E6: 802.96389
C7: E01300 | D7: C010101 | E7: 10477.008
C8: E01300 | D8: C010105 | E8: 8264.6339 | H8: Row Labels | I8: Sum of Amount
C9: E01300 | D9: C010110 | E9: 2712.9732 | H9: E00330 | I9: 28628.794
C10: E01300 | D10: C010111 | E10: 5686.7714 | H10: E01300 | I10: 8646841.1
C11: E01300 | D11: C010115 | E11: 5762.7926 | H11: Grand Total | I11: 8675469.9
C12: E01300 | D12: C010121 | E12: 4818.8518
C13: E01300 | D13: C010122 | E13: 16824.506
C14: E01300 | D14: C010124 | E14: 6416.1809
C15: E01300 | D15: C010127 | E15: 6279.5458
C16: E01300 | D16: C010150 | E16: 4506.3536
C17: E01300 | D17: C010205 | E17: 3027.9537
C18: E01300 | D18: C010210 | E18: 12755.259
C19: E01300 | D19: C010215 | E19: 13752.606
C20: E01300 | D20: C010220 | E20: 14829.946
C21: E01300 | D21: C010230 | E21: 14758.68
C22: E01300 | D22: C010301 | E22: 9801.7422
C23: E01300 | D23: C010305 | E23: 12111.828
... C709: E01300 | D709: C515008 | E709: 1054.8229

Sheet Cash Calc.
A2: Row Labels | B2: Sum of FTE | C2: Health & Welfare Expense | D2: Cost/FTE | E2: Segment H&W
A3: Corporate | B3: 2421 | E3: =B3*$D$6 -> 2059754.1 | F3: =GETPIVOTDATA("FTE",$A$2,"Segment","Corporate")/GETPIVOTDATA("FTE",$A$2) -> 0.23742277
A4: Housing | B4: 4318 | E4: =B4*$D$6 -> 3673696.1 | F4: =GETPIVOTDATA("FTE",$A$2,"Segment","Housing")/GETPIVOTDATA("FTE",$A$2) -> 0.42345788
A5: Lifestyle | B5: 3458 | E5: =B5*$D$6 -> 2942019.7 | F5: =GETPIVOTDATA("FTE",$A$2,"Segment","Lifestyle")/GETPIVOTDATA("FTE",$A$2) -> 0.33911935
A6: Grand Total | B6: 10197 | C6: ='GFS Cube'!C14 -> 8675469.9 | D6: =C6/GETPIVOTDATA("FTE",$A$2) -> 850.78649 | E6: =SUM(E3:E5) -> 8675469.9
A8: Segment | B8: Corporate | H8: Segment | I8: Housing | O8: Segment | P8: Lifestyle
A10: Sum of Salary | H10: Sum of Salary | O10: Sum of Salary
A11: Entity_Code | B11: Center_Code | C11: Total | D11: % of Salary | E11: H&W per CC | F11: Load Rate | H11: Entity_Code | I11: Center_Code | J11: Total | K11: % of Salary | L11: H&W per CC | M11: Load Rate | O11: Entity_Code | P11: Center_Code | Q11: Total | R11: % of Salary | S11: H&W per CC | T11: Load Rate
A12: E00330 | B12: C040414 | C12: 1676 | D12: =C12/$C$282 -> 0.00013843672 | E12: =D12*$E$3 -> 285.1456 | F12: =E12/C12 -> 0.17013461 | H12: E00330 | I12: C301007 | J12: 3576.92 | K12: =J12/$J$216 -> 0.00037666482 | L12: =K12*$E$4 -> 1383.7521 | M12: =L12/J12 -> 0.38685575 | O12: E01300 | P12: C010155 | Q12: 25526.54 | R12: =Q12/$Q$244 -> 0.0027994999 | S12: =R12*$E$5 -> 8236.1838 | T12: =S12/Q12 -> 0.32265179
A13: E01300 | B13: C010000 | C13: 32448.88 | D13: =C13/$C$282 -> 0.0026802604 | E13: =D13*$E$3 -> 5520.6774 | F13: =E13/C13 -> 0.17013461 | H13: E00330 | I13: C301008 | J13: 4769.23 | K13: =J13/$J$216 -> 0.00050222011 | L13: =K13*$E$4 -> 1845.0041 | M13: =L13/J13 -> 0.38685575 | O13: E01300 | P13: C010160 | Q13: 49363.46 | R13: =Q13/$Q$244 -> 0.0054136989 | S13: =R13*$E$5 -> 15927.209 | T13: =S13/Q13 -> 0.32265179
A14: E01300 | B14: C010011 | C14: 4719.58 | D14: =C14/$C$282 -> 0.00038983483 | E14: =D14*$E$3 -> 802.96389 | F14: =E14/C14 -> 0.17013461 | H14: E00330 | I14: C350102 | J14: 4876.65 | K14: =J14/$J$216 -> 0.00051353189 | L14: =K14*$E$4 -> 1886.5601 | M14: =L14/J14 -> 0.38685575 | O14: E01300 | P14: C010162 | Q14: 92640.3 | R14: =Q14/$Q$244 -> 0.010159877 | S14: =R14*$E$5 -> 29890.559 | T14: =S14/Q14 -> 0.32265179
A15: E01300 | B15: C010101 | C15: 61580.7 | D15: =C15/$C$282 -> 0.0050865335 | E15: =D15*$E$3 -> 10477.008 | F15: =E15/C15 -> 0.17013461 | H15: E00330 | I15: C350103 | J15: 7224.19 | K15: =J15/$J$216 -> 0.00076073779 | L15: =K15*$E$4 -> 2794.7194 | M15: =L15/J15 -> 0.38685575 | O15: E01300 | P15: C010163 | Q15: 47526.69 | R15: =Q15/$Q$244 -> 0.00521226 | S15: =R15*$E$5 -> 15334.572 | T15: =S15/Q15 -> 0.32265179
A16: E01300 | B16: C010105 | C16: 48577.03 | D16: =C16/$C$282 -> 0.0040124372 | E16: =D16*$E$3 -> 8264.6339 | F16: =E16/C16 -> 0.17013461 | H16: E00330 | I16: C350106 | J16: 3556.88 | K16: =J16/$J$216 -> 0.00037455452 | L16: =K16*$E$4 -> 1375.9995 | M16: =L16/J16 -> 0.38685575 | O16: E01300 | P16: C010164 | Q16: 179021.21 | R16: =Q16/$Q$244 -> 0.019633286 | S16: =R16*$E$5 -> 57761.514 | T16: =S16/Q16 -> 0.32265179
A17: E01300 | B17: C010110 | C17: 15946.04 | D17: =C17/$C$282 -> 0.0013171345 | E17: =D17*$E$3 -> 2712.9732 | F17: =E17/C17 -> 0.17013461 | H17: E00330 | I17: C350110 | J17: 10415.43 | K17: =J17/$J$216 -> 0.0010967889 | L17: =K17*$E$4 -> 4029.269 | M17: =L17/J17 -> 0.38685575 | O17: E01300 | P17: C010180 | Q17: 34692.52 | R17: =Q17/$Q$244 -> 0.0038047344 | S17: =R17*$E$5 -> 11193.604 | T17: =S17/Q17 -> 0.32265179
A18: E01300 | B18: C010111 | C18: 33425.13 | D18: =C18/$C$282 -> 0.0027608982 | E18: =D18*$E$3 -> 5686.7714 | F18: =E18/C18 -> 0.17013461 | H18: E00330 | I18: C350512 | J18: 2178.72 | K18: =J18/$J$216 -> 0.00022942844 | L18: =K18*$E$4 -> 842.85036 | M18: =L18/J18 -> 0.38685575 | O18: E01300 | P18: C010450 | Q18: 58345.65 | R18: =Q18/$Q$244 -> 0.0063987772 | S18: =R18*$E$5 -> 18825.328 | T18: =S18/Q18 -> 0.32265179
A19: E01300 | B19: C010115 | C19: 33871.96 | D19: =C19/$C$282 -> 0.0027978061 | E19: =D19*$E$3 -> 5762.7926 | F19: =E19/C19 -> 0.17013461 | H19: E00330 | I19: C350520 | J19: 1920.9 | K19: =J19/$J$216 -> 0.0002022789 | L19: =K19*$E$4 -> 743.11121 | M19: =L19/J19 -> 0.38685575 | O19: E01300 | P19: C010451 | Q19: 49717.2 | R19: =Q19/$Q$244 -> 0.0054524936 | S19: =R19*$E$5 -> 16041.344 | T19: =S19/Q19 -> 0.32265179
A20: E01300 | B20: C010121 | C20: 28323.76 | D20: =C20/$C$282 -> 0.0023395277 | E20: =D20*$E$3 -> 4818.8518 | F20: =E20/C20 -> 0.17013461 | H20: E00330 | I20: C350527 | J20: 1838.16 | K20: =J20/$J$216 -> 0.00019356603 | L20: =K20*$E$4 -> 711.10277 | M20: =L20/J20 -> 0.38685575 | O20: E01300 | P20: C010452 | Q20: 87773.73 | R20: =Q20/$Q$244 -> 0.0096261596 | S20: =R20*$E$5 -> 28320.351 | T20: =S20/Q20 -> 0.32265179
A21: E01300 | B21: C010122 | C21: 98889.38 | D21: =C21/$C$282 -> 0.0081682109 | E21: =D21*$E$3 -> 16824.506 | F21: =E21/C21 -> 0.17013461 | H21: E00330 | I21: C350529 | J21: 5145.18 | K21: =J21/$J$216 -> 0.00054180924 | L21: =K21*$E$4 -> 1990.4425 | M21: =L21/J21 -> 0.38685575 | O21: E01300 | P21: C010453 | Q21: 10748.96 | R21: =Q21/$Q$244 -> 0.0011788402 | S21: =R21*$E$5 -> 3468.1712 | T21: =S21/Q21 -> 0.32265179
A22: E01300 | B22: C010124 | C22: 37712.38 | D22: =C22/$C$282 -> 0.0031150228 | E22: =D22*$E$3 -> 6416.1809 | F22: =E22/C22 -> 0.17013461 | H22: E00330 | I22: C350553 | J22: 4440.77 | K22: =J22/$J$216 -> 0.00046763188 | L22: =K22*$E$4 -> 1717.9374 | M22: =L22/J22 -> 0.38685575 | O22: E01300 | P22: C303058 | Q22: 13673.24 | R22: =Q22/$Q$244 -> 0.0014995465 | S22: =R22*$E$5 -> 4411.6954 | T22: =S22/Q22 -> 0.32265179
A23: E01300 | B23: C010127 | C23: 36909.28 | D23: =C23/$C$282 -> 0.0030486871 | E23: =D23*$E$3 -> 6279.5458 | F23: =E23/C23 -> 0.17013461 | H23: E00330 | I23: C350557 | J23: 2737.6 | K23: =J23/$J$216 -> 0.00028828087 | L23: =K23*$E$4 -> 1059.0563 | M23: =L23/J23 -> 0.38685575 | O23: E01300 | P23: C380000 | Q23: 110052.64 | R23: =Q23/$Q$244 -> 0.012069491 | S23: =R23*$E$5 -> 35508.681 | T23: =S23/Q23 -> 0.32265179
... A215: E01300 | B215: C252121 | C215: 51350.42 | D215: =C215/$C$282 -> 0.0042415177 | E215: =D215*$E$3 -> 8736.4835 | F215: =E215/C215 -> 0.17013461 | H215: E01300 | I215: C350726 | J215: 5006.62 | K215: =J215/$J$216 -> 0.00052721828 | L215: =K215*$E$4 -> 1936.8397 | M215: =L215/J215 -> 0.38685575 | O215: E01300 | P215: C385008 | Q215: 37639.08 | R215: =Q215/$Q$244 -> 0.0041278842 | S215: =R215*$E$5 -> 12144.317 | T215: =S215/Q215 -> 0.32265179
A216: E01300 | B216: C252124 | C216: 39442.97 | D216: =C216/$C$282 -> 0.0032579686 | E216: =D216*$E$3 -> 6710.6142 | F216: =E216/C216 -> 0.17013461 | H216: Grand Total | J216: 9496294.3 | K216: =J216/$J$216 -> 1 | L216: =K216*$E$4 -> 3673696.1 | M216: =L216/J216 -> 0.38685575 | O216: E01300 | P216: C385009 | Q216: 49907.98 | R216: =Q216/$Q$244 -> 0.0054734165 | S216: =R216*$E$5 -> 16102.899 | T216: =S216/Q216 -> 0.32265179
A217: E01300 | B217: C252125 | C217: 22290.2 | D217: =C217/$C$282 -> 0.0018411588 | E217: =D217*$E$3 -> 3792.3344 | F217: =E217/C217 -> 0.17013461 | O217: E01300 | P217: C503061 | Q217: 79982.02 | R217: =Q217/$Q$244 -> 0.0087716415 | S217: =R217*$E$5 -> 25806.342 | T217: =S217/Q217 -> 0.32265179
A218: E01300 | B218: C252129 | C218: 12642.24 | D218: =C218/$C$282 -> 0.0010442424 | E218: =D218*$E$3 -> 2150.8825 | F218: =E218/C218 -> 0.17013461 | O218: E01300 | P218: C505104 | Q218: 95201.45 | R218: =Q218/$Q$244 -> 0.010440759 | S218: =R218*$E$5 -> 30716.918 | T218: =S218/Q218 -> 0.32265179
A219: E01300 | B219: C252131 | C219: 58752.46 | D219: =C219/$C$282 -> 0.0048529223 | E219: =D219*$E$3 -> 9995.8267 | F219: =E219/C219 -> 0.17013461 | O219: E01300 | P219: C506034 | Q219: 18714.19 | R219: =Q219/$Q$244 -> 0.0020523883 | S219: =R219*$E$5 -> 6038.1669 | T219: =S219/Q219 -> 0.32265179
A220: E01300 | B220: C252133 | C220: 8857.54 | D220: =C220/$C$282 -> 0.00073162815 | E220: =D220*$E$3 -> 1506.9741 | F220: =E220/C220 -> 0.17013461 | O220: E01300 | P220: C380018 | Q220: 11101.81 | R220: =Q220/$Q$244 -> 0.0012175374 | S220: =R220*$E$5 -> 3582.0189 | T220: =S220/Q220 -> 0.32265179
A221: E01300 | B221: C253002 | C221: 88144.83 | D221: =C221/$C$282 -> 0.0072807167 | E221: =D221*$E$3 -> 14996.486 | F221: =E221/C221 -> 0.17013461 | O221: E01300 | P221: C505103 | Q221: 83243.19 | R221: =Q221/$Q$244 -> 0.0091292945 | S221: =R221*$E$5 -> 26858.564 | T221: =S221/Q221 -> 0.32265179
A222: E01300 | B222: C253005 | C222: 31684.85 | D222: =C222/$C$282 -> 0.002617152 | E222: =D222*$E$3 -> 5390.6895 | F222: =E222/C222 -> 0.17013461 | O222: E01300 | P222: C505105 | Q222: 112267.79 | R222: =Q222/$Q$244 -> 0.012312427 | S222: =R222*$E$5 -> 36223.403 | T222: =S222/Q222 -> 0.32265179
A223: E01300 | B223: C253011 | C223: 27653.93 | D223: =C223/$C$282 -> 0.0022842001 | E223: =D223*$E$3 -> 4704.8905 | F223: =E223/C223 -> 0.17013461 | O223: E01300 | P223: C400124 | Q223: 28153.86 | R223: =Q223/$Q$244 -> 0.0030876385 | S223: =R223*$E$5 -> 9083.8933 | T223: =S223/Q223 -> 0.32265179
A224: E01300 | B224: C253012 | C224: 166398.93 | D224: =C224/$C$282 -> 0.013744464 | E224: =D224*$E$3 -> 28310.217 | F224: =E224/C224 -> 0.17013461 | O224: E01300 | P224: C505100 | Q224: 44420.41 | R224: =Q224/$Q$244 -> 0.0048715938 | S224: =R224*$E$5 -> 14332.325 | T224: =S224/Q224 -> 0.32265179
A225: E01300 | B225: C253013 | C225: 54379.05 | D225: =C225/$C$282 -> 0.004491681 | E225: =D225*$E$3 -> 9251.7583 | F225: =E225/C225 -> 0.17013461 | O225: E01300 | P225: C500369 | Q225: 49408.72 | R225: =Q225/$Q$244 -> 0.0054186626 | S225: =R225*$E$5 -> 15941.812 | T225: =S225/Q225 -> 0.32265179
A226: E01300 | B226: C253014 | C226: 19426.67 | D226: =C226/$C$282 -> 0.0016046327 | E226: =D226*$E$3 -> 3305.1489 | F226: =E226/C226 -> 0.17013461 | O226: E01300 | P226: C506072 | Q226: 28767.12 | R226: =Q226/$Q$244 -> 0.0031548948 | S226: =R226*$E$5 -> 9281.7628 | T226: =S226/Q226 -> 0.32265179
A227: E01300 | B227: C253015 | C227: 10728.69 | D227: =C227/$C$282 -> 0.00088618416 | E227: =D227*$E$3 -> 1825.3215 | F227: =E227/C227 -> 0.17013461 | O227: E01300 | P227: C506073 | Q227: 17566.17 | R227: =Q227/$Q$244 -> 0.0019264848 | S227: =R227*$E$5 -> 5667.7562 | T227: =S227/Q227 -> 0.32265179
A228: E01300 | B228: C253019 | C228: 46078.3 | D228: =C228/$C$282 -> 0.0038060434 | E228: =D228*$E$3 -> 7839.5135 | F228: =E228/C228 -> 0.17013461 | O228: E01300 | P228: C500370 | Q228: 18059.57 | R228: =Q228/$Q$244 -> 0.0019805961 | S228: =R228*$E$5 -> 5826.9526 | T228: =S228/Q228 -> 0.32265179
... A243: E01300 | B243: C253710 | C243: 11514.89 | D243: =C243/$C$282 -> 0.00095112387 | E243: =D243*$E$3 -> 1959.0813 | F243: =E243/C243 -> 0.17013461 | O243: E01300 | P243: C515008 | Q243: 3269.23 | R243: =Q243/$Q$244 -> 0.000358537 | S243: =R243*$E$5 -> 1054.8229 | T243: =S243/Q243 -> 0.32265179
A244: E01300 | B244: C253711 | C244: 102379.41 | D244: =C244/$C$282 -> 0.0084564855 | E244: =D244*$E$3 -> 17418.281 | F244: =E244/C244 -> 0.17013461 | O244: Grand Total | Q244: 9118250 | R244: =Q244/$Q$244 -> 1 | S244: =R244*$E$5 -> 2942019.7 | T244: =S244/Q244 -> 0.32265179
A245: E01300 | B245: C253712 | C245: 82720.13 | D245: =C245/$C$282 -> 0.0068326393 | E245: =D245*$E$3 -> 14073.557 | F245: =E245/C245 -> 0.17013461
A246: E01300 | B246: C253714 | C246: 53163.87 | D246: =C246/$C$282 -> 0.0043913077 | E246: =D246*$E$3 -> 9045.0141 | F246: =E246/C246 -> 0.17013461
A247: E01300 | B247: C253716 | C247: 9550.69 | D247: =C247/$C$282 -> 0.00078888198 | E247: =D247*$E$3 -> 1624.9029 | F247: =E247/C247 -> 0.17013461
A248: E01300 | B248: C253722 | C248: 24218.97 | D248: =C248/$C$282 -> 0.0020004742 | E248: =D248*$E$3 -> 4120.4849 | F248: =E248/C248 -> 0.17013461
...

Sheet Salary-FTE
A1: October 2025 Salaries per Cost Center | I1: Salary posted to the default CC C200591 is excluded from the allocation process
A3: Entity_Code | B3: Center_Code | C3: FTE | D3: Salary | E3: Segment
A4: E00330 | B4: C040414 | C4: 0 | D4: 1676 | E4: =VLOOKUP(B4,'CC by Segment'!$D:$E,2,FALSE) -> Corporate | G4: =TRIM(B4) -> C040414
A5: E00330 | B5: C301007 | C5: 0 | D5: 3576.92 | E5: =VLOOKUP(B5,'CC by Segment'!$D:$E,2,FALSE) -> Housing | G5: =TRIM(B5) -> C301007
A6: E00330 | B6: C301008 | C6: 0 | D6: 4769.23 | E6: =VLOOKUP(B6,'CC by Segment'!$D:$E,2,FALSE) -> Housing | G6: =TRIM(B6) -> C301008
A7: E00330 | B7: C350102 | C7: 0 | D7: 4876.65 | E7: =VLOOKUP(B7,'CC by Segment'!$D:$E,2,FALSE) -> Housing | G7: =TRIM(B7) -> C350102
A8: E00330 | B8: C350103 | C8: 0 | D8: 7224.19 | E8: =VLOOKUP(B8,'CC by Segment'!$D:$E,2,FALSE) -> Housing | G8: =TRIM(B8) -> C350103
A9: E00330 | B9: C350106 | C9: 0 | D9: 3556.88 | E9: =VLOOKUP(B9,'CC by Segment'!$D:$E,2,FALSE) -> Housing | G9: =TRIM(B9) -> C350106
A10: E00330 | B10: C350110 | C10: 0 | D10: 10415.43 | E10: =VLOOKUP(B10,'CC by Segment'!$D:$E,2,FALSE) -> Housing | G10: =TRIM(B10) -> C350110
A11: E00330 | B11: C350512 | C11: 0 | D11: 2178.72 | E11: =VLOOKUP(B11,'CC by Segment'!$D:$E,2,FALSE) -> Housing | G11: =TRIM(B11) -> C350512
A12: E00330 | B12: C350520 | C12: 0 | D12: 1920.9 | E12: =VLOOKUP(B12,'CC by Segment'!$D:$E,2,FALSE) -> Housing | G12: =TRIM(B12) -> C350520
A13: E00330 | B13: C350527 | C13: 0 | D13: 1838.16 | E13: =VLOOKUP(B13,'CC by Segment'!$D:$E,2,FALSE) -> Housing | G13: =TRIM(B13) -> C350527
A14: E00330 | B14: C350529 | C14: 0 | D14: 5145.18 | E14: =VLOOKUP(B14,'CC by Segment'!$D:$E,2,FALSE) -> Housing | G14: =TRIM(B14) -> C350529
A15: E00330 | B15: C350553 | C15: 0 | D15: 4440.77 | E15: =VLOOKUP(B15,'CC by Segment'!$D:$E,2,FALSE) -> Housing | G15: =TRIM(B15) -> C350553
... A157: E01300 | B157: C200561 | C157: 5 | D157: 22199.57 | E157: =VLOOKUP(B157,'CC by Segment'!$D:$E,2,FALSE) -> Corporate | G157: =TRIM(B157) -> C200561
A158: E01300 | B158: C200591 | C158: 0 | D158: 2470.14 | E158: 0 | G158: =TRIM(B158) -> C200591
A159: E01300 | B159: C200601 | C159: 3 | D159: 25784.66 | E159: =VLOOKUP(B159,'CC by Segment'!$D:$E,2,FALSE) -> Corporate | G159: =TRIM(B159) -> C200601
A160: E01300 | B160: C250000 | C160: 2 | D160: 23077.92 | E160: =VLOOKUP(B160,'CC by Segment'!$D:$E,2,FALSE) -> Corporate | G160: =TRIM(B160) -> C250000
A161: E01300 | B161: C250050 | C161: 12 | D161: 48754.67 | E161: =VLOOKUP(B161,'CC by Segment'!$D:$E,2,FALSE) -> Corporate | G161: =TRIM(B161) -> C250050
A162: E01300 | B162: C250051 | C162: 12 | D162: 53479.56 | E162: =VLOOKUP(B162,'CC by Segment'!$D:$E,2,FALSE) -> Corporate | G162: =TRIM(B162) -> C250051
A163: E01300 | B163: C250052 | C163: 5 | D163: 30261.19 | E163: =VLOOKUP(B163,'CC by Segment'!$D:$E,2,FALSE) -> Corporate | G163: =TRIM(B163) -> C250052
A164: E01300 | B164: C250100 | C164: 8 | D164: 39109.81 | E164: =VLOOKUP(B164,'CC by Segment'!$D:$E,2,FALSE) -> Corporate | G164: =TRIM(B164) -> C250100
A165: E01300 | B165: C250110 | C165: 5 | D165: 24707.72 | E165: =VLOOKUP(B165,'CC by Segment'!$D:$E,2,FALSE) -> Corporate | G165: =TRIM(B165) -> C250110
A166: E01300 | B166: C250112 | C166: 11 | D166: 45341.22 | E166: =VLOOKUP(B166,'CC by Segment'!$D:$E,2,FALSE) -> Corporate | G166: =TRIM(B166) -> C250112
A167: E01300 | B167: C250113 | C167: 1 | D167: 12580.04 | E167: =VLOOKUP(B167,'CC by Segment'!$D:$E,2,FALSE) -> Corporate | G167: =TRIM(B167) -> C250113
A168: E01300 | B168: C250120 | C168: 8 | D168: 31388.35 | E168: =VLOOKUP(B168,'CC by Segment'!$D:$E,2,FALSE) -> Corporate | G168: =TRIM(B168) -> C250120
A169: E01300 | B169: C250122 | C169: 18 | D169: 65709.81 | E169: =VLOOKUP(B169,'CC by Segment'!$D:$E,2,FALSE) -> Corporate | G169: =TRIM(B169) -> C250122
A170: E01300 | B170: C250123 | C170: 19 | D170: 94680.87 | E170: =VLOOKUP(B170,'CC by Segment'!$D:$E,2,FALSE) -> Corporate | G170: =TRIM(B170) -> C250123
... A710: E01300 | B710: C350726 | C710: 1 | D710: 5006.62 | E710: =VLOOKUP(B710,'CC by Segment'!$D:$E,2,FALSE) -> Housing | G710: =TRIM(B710) -> C350726
C711: =SUM(C4:C710) -> 10197 | D711: =SUM(D4:D710) -> 30723629

Sheet Email

Sheet FTE
A1: October 2025 FTE per Cost Center | H1: Salary posted to the default CC C200591 is excluded from the allocation process
A3: Entity_Code | B3: Center_Code | C3: FTE | E3: Rate | F3: ='Cash Calc.'!D6 -> 850.78649
A4: E00330 | B4: C040414 | C4: 0 | F4: =C4*$F$3 -> 0
A5: E00330 | B5: C301007 | C5: 0 | F5: =C5*$F$3 -> 0
A6: E00330 | B6: C301008 | C6: 0 | F6: =C6*$F$3 -> 0
A7: E00330 | B7: C350102 | C7: 0 | F7: =C7*$F$3 -> 0
A8: E00330 | B8: C350103 | C8: 0 | F8: =C8*$F$3 -> 0
A9: E00330 | B9: C350106 | C9: 0 | F9: =C9*$F$3 -> 0
A10: E00330 | B10: C350110 | C10: 0 | F10: =C10*$F$3 -> 0
A11: E00330 | B11: C350512 | C11: 0 | F11: =C11*$F$3 -> 0
A12: E00330 | B12: C350520 | C12: 0 | F12: =C12*$F$3 -> 0
A13: E00330 | B13: C350527 | C13: 0 | F13: =C13*$F$3 -> 0
A14: E00330 | B14: C350529 | C14: 0 | F14: =C14*$F$3 -> 0
A15: E00330 | B15: C350553 | C15: 0 | F15: =C15*$F$3 -> 0
... A710: E01300 | B710: C350726 | C710: 1 | F710: =C710*$F$3 -> 850.78649
C711: =SUM(C4:C710) -> 10197

Sheet GFS Cube
A2: Hier_Consol Sub Account Code Desc | B2: All
A3: Ledger Name | B3: (Multiple Items)
A4: GFSDM Last Updated | B4: All
A5: Dataset Last Refreshed | B5: All
B7: Column Labels
B8: 2025
B9: Oct-2025
A10: Row Labels | B10: Func Cur YTD | C10: USD Cur YTD
A11: E01300:American Bankers Insurance Company of Florida
A12: A700018-00:Group Ins - Emp Company Cost
A13: C200593:Group Insurance
A14: B000 | B14: 8675469.9 | C14: 8675469.9
A15: B100 | B15: 722467.74 | C15: 722467.74

Sheet Account
A1: GFS Sub account | B1: Account Description | C1: SS account | D1: Type Code (as a reference, not meant to be exhaustive list) | E1: Date of Changes | I1: SS Account GFS | J1: GFS Account (check) | K1: In EDM Yes/No
A2: A105098-00 | B2: Inv Def Comp - Executive 401k Plan | C2: 12060000 | D2: MIPSP | J2: A105098-00 | K2: Yes
A3: A105099-00 | B3: Invested Deferred Compensation Asset | C3: 12062000 | J3: A105099-00 | K3: Yes
A4: A105099-01 | B4: Inv Def Comp - Frozen Plans | C4: 12062000 | D4: FOR | J4: A105099-01 | K4: Yes
A5: A105099-02 | B5: Inv Def Comp - Active Plans | C5: 12062000 | D5: ADC | J5: A105099-02 | K5: Yes
A6: A105100-00 | B6: Policy Loans - Dir | C6: 10500000 | D6: Policy Loans | J6: A105100-00 | K6: Yes
A7: A105111-00 | B7: Loans Loss Reserve | C7: 10480001 | J7: A105111-00 | K7: Yes
A8: A105200-00 | B8: Policy Loans - Asmd NonAffil | C8: 10500100 | J8: A105200-00 | K8: Yes
A9: A105300-00 | B9: Policy Loans - Ced NonAffil | C9: 10500200 | J9: A105300-00 | K9: Yes
A10: A105900-00 | B10: Policy Loans - NonAdmit | C10: 10500600 | J10: A105900-00 | K10: Yes
A11: A1T0017-00 | B11: ST Inv Other Non Aflt | C11: 10099000 | J11: A1T0017-00 | K11: Yes
A12: A1T0108-00 | B12: Csh In Office | C12: 10800000 | J12: A1T0108-00 | K12: Yes
A13: A1T0126-00 | B13: Cash Other | C13: 10899000 | J13: A1T0126-00 | K13: Yes
A14: A115000-00 | B14: Due To (From) Parent and Affiliates | C14: 14300000 | D14: (add appropriate affil) | J14: A115000-00 | K14: Yes
A15: A115000-00 | B15: Due To (From) Parent and Affiliates | C15: 14208101 | D15: E00901 | J15: A115000-00 | K15: Yes
A16: A115000-00 | B16: Due To (From) Parent and Affiliates | C16: 14208186 | D16: E00730 | J16: A115000-00 | K16: Yes
A17: A115000-00 | B17: Due To (From) Parent and Affiliates | C17: 14208530 | D17: E00721 | J17: A115000-00 | K17: Yes
A18: A115000-00 | B18: Due To (From) Parent and Affiliates | C18: 14208532 | D18: E00711 | J18: A115000-00 | K18: Yes
A19: A115000-00 | B19: Due To (From) Parent and Affiliates | C19: 14208534 | D19: E00711 | J19: A115000-00 | K19: Yes
A20: A115000-00 | B20: Due To (From) Parent and Affiliates | C20: 14208640 | D20: E00912 | J20: A115000-00 | K20: Yes
A21: A115000-00 | B21: Due To (From) Parent and Affiliates | C21: 14301000 | D21: E00001 | J21: A115000-00 | K21: Yes
A22: A115000-00 | B22: Due To (From) Parent and Affiliates | C22: 14308001 | D22: E00330 | J22: A115000-00 | K22: Yes
A23: A115000-00 | B23: Due To (From) Parent and Affiliates | C23: 14308005 | D23: E00302 | J23: A115000-00 | K23: Yes
A24: A115000-00 | B24: Due To (From) Parent and Affiliates | C24: 14308008 | D24: E00301 | J24: A115000-00 | K24: Yes
A25: A115000-00 | B25: Due To (From) Parent and Affiliates | C25: 14308101 | D25: E00901 | J25: A115000-00 | K25: Yes
... A145: A115000-00 | B145: Due To (From) Parent and Affiliates | C145: 14308989 | D145: E01200 | J145: A115000-00 | K145: Yes
A146: A115000-00 | B146: Due To (From) Parent and Affiliates | C146: 14208V09 | D146: E00530 | J146: A115000-00 | K146: Yes
A147: A115000-00 | B147: Due To (From) Parent and Affiliates | C147: 14208V17 | D147: E00531 | J147: A115000-00 | K147: Yes
A148: A115000-00 | B148: Due To (From) Parent and Affiliates | C148: 14308IA2 | D148: E00804 | J148: A115000-00 | K148: Yes
A149: A115000-00 | B149: Due To (From) Parent and Affiliates | C149: 14308IA3 | D149: E00805 | J149: A115000-00 | K149: Yes
A150: A115000-00 | B150: Due To (From) Parent and Affiliates | C150: 14308IAT | D150: E00631 | J150: A115000-00 | K150: Yes
A151: A115000-00 | B151: Due To (From) Parent and Affiliates | C151: 14308IAU | D151: E00632 | J151: A115000-00 | K151: Yes
A152: A115000-00 | B152: Due To (From) Parent and Affiliates | C152: 14308IAV | D152: E00635 | J152: A115000-00 | K152: Yes
A153: A115000-00 | B153: Due To (From) Parent and Affiliates | C153: 14308IBC | D153: E00809 | J153: A115000-00 | K153: Yes
A154: A115000-00 | B154: Due To (From) Parent and Affiliates | C154: 14308IBS | D154: E00909 | J154: A115000-00 | K154: Yes
A155: A115000-00 | B155: Due To (From) Parent and Affiliates | C155: 14308IBZ | D155: E00821 | J155: A115000-00 | K155: Yes
A156: A115000-00 | B156: Due To (From) Parent and Affiliates | C156: 14308ICD | D156: E00806 | J156: A115000-00 | K156: Yes
A157: A115000-00 | B157: Due To (From) Parent and Affiliates | C157: 14308ICL | D157: E00808 | J157: A115000-00 | K157: Yes
... A197: A115000-00 | B197: Due To (From) Parent and Affiliates | C197: 14308V17 | D197: E00531 | J197: A115000-00 | K197: Yes
A198: A115000-00 | B198: Due To (From) Parent and Affiliates | C198: 14301020 | D198: E00300 | J198: A115000-00 | K198: Yes
...

Sheet Cost Center
A1: SS Cost Center | B1: SS Cost Center Description | C1: GFS Center | D1: GFS Center Description | F1: Location Code | G1: Descriptions | H1: In EDM Yes/No
A2: 113040 | B2: 113040-Office Of CFO | C2: C010000 | D2: Finance - Chief Financial Officer | F2: L0001 | G2: U.S. Home Office | H2: Yes | I2: 113040
A3: 2005 | B3: 2005-Reinsurance Marketing | C3: C400030 | D3: Global Auto - Reinsurance Marketing | F3: L0001 | G3: U.S. Home Office | H3: Yes | I3: 2005
A4: 11112 | B4: 11112-CLAIMS ACCOUNTING DFS | C4: C010101 | D4: Global Accouting - CAO | F4: L0001 | G4: U.S. Home Office | H4: Yes | I4: 11112
A5: 2015 | B5: 2015-CarMax & Digital Auto | C5: C400025 | D5: Global Auto - CarMax & Digital Auto | H5: Yes | I5: 2015
A6: 2035 | B6: 2035-Pacific NW | C6: C400115 | D6: Global Auto - ADS - Pacific NW | H6: Yes | I6: 2035
A7: 1013402 | B7: 1013402-Investment Accounting | C7: C010105 | D7: Global Accounting - Investments | F7: L0001 | G7: U.S. Home Office | H7: Yes | I7: 1013402
A8: 113230 | B8: 113230-Financial And Sec Reporting | C8: C010110 | D8: Global Accounting - Financial and SEC Reporting | F8: L0001 | G8: U.S. Home Office | H8: Yes | I8: 113230
A9: 2075 | B9: 2075-Workforce Management | C9: C380008 | D9: VPS Ops - Workforce Management | H9: Yes | I9: 2075
A10: 3015 | B10: 3015-Service Admin-Chicago | C10: C515305 | D10: CL - HRO - TWG - Service Admin-Chicago | F10: L0001 | G10: U.S. Home Office | H10: Yes | I10: 3015
A11: 113049 | B11: 113049-Accounting & Finance Services | C11: C010121 | D11: Global Accounting - AFS Admin | F11: L0001 | G11: U.S. Home Office | H11: Yes | I11: 113049
A12: 5002 | B12: 5002:NETWORK AND SYSTEMS | C12: C254015 | D12: GT - TWG Apps - Network and Systems | H12: Yes | I12: 5002
A13: 5003 | B13: 5003:SECURITY PHOENIX | C13: C254019 | D13: GT - TWG Apps - Security Phoenix | H13: Yes | I13: 5003
A14: 5007 | B14: 5007-Help Desk & Desktop Spprt | C14: C254009 | D14: GT - TWG Apps - Help Desk and Desktop Support | F14: L0001 | G14: U.S. Home Office | H14: Yes | I14: 5007
A15: 5012 | B15: 5012:GLOW PROGRAM SOFTWARE | C15: C254007 | D15: GT - TWG Apps - GLOW Program Software | H15: Yes | I15: 5012
A16: 5013 | B16: 5013-IT Executive | C16: C254013 | D16: GT - TWG Apps - IT Executive | F16: L0001 | G16: U.S. Home Office | H16: Yes | I16: 5013
A17: 5014 | B17: 5014:GLOW & AIM LIFESTYLE PROJECT | C17: C254023 | D17: GT - TWG Apps - GLOW AIM Lifestyle Project | H17: Yes | I17: 5014
A18: 5015 | B18: 5015:TWG PUBLIC CLOUD | C18: C254017 | D18: GT - TWG Apps - Public Cloud | H18: Yes | I18: 5015
A19: 5016 | B19: 5016:LEGACY SYSTEM SUPPORT | C19: C254014 | D19: GT - TWG Apps - Legacy System Support | H19: Yes | I19: 5016
A20: 5017 | B20: 5017- UDB & AIM | C20: C254021 | D20: GT - TWG Apps - UDB & AIM | F20: L0001 | G20: U.S. Home Office | H20: Yes | I20: 5017
A21: 10200 | B21: 10200-LFS Segment Financial Reporting | C21: C010160 | D21: Global Accounting - Lifestyle Financial Reporting | F21: L0001 | G21: U.S. Home Office | H21: Yes | I21: 10200
A22: 10202 | B22: 10202-FIN REP MIA CROSS SELL ELIMINATIONS | C22: C010160 | D22: Global Accounting - Lifestyle Financial Reporting | F22: L0001 | G22: U.S. Home Office | H22: Yes | I22: 10202
A23: 6019 | B23: 6019-External Reporting | C23: C010160 | D23: Global Accounting - Lifestyle Financial Reporting | F23: L0001 | G23: U.S. Home Office | H23: Yes | I23: 6019
A24: 10271 | B24: 10271-CL Operations | C24: C010161 | D24: Global Accounting - Connected Living Acctg Ops | F24: L0001 | G24: U.S. Home Office | H24: Yes | I24: 10271
A25: 10228 | B25: 10228-GENERAL ACCOUNTING S&R | C25: C010162 | D25: Global Accounting - Mobile Accounting | F25: L0001 | G25: U.S. Home Office | H25: Yes | I25: 10228
A26: 5019 | B26: 5019- Cloud Technologies | C26: C254004 | D26: GT - TWG Apps - Cloud Technologies | F26: L0001 | G26: U.S. Home Office | H26: Yes | I26: 5019
A27: 10272 | B27: 10272-Mobile Accounting | C27: C010162 | D27: Global Accounting - Mobile Accounting | F27: L0001 | G27: U.S. Home Office | H27: Yes | I27: 10272
A28: WS712 | B28: WS712-GEN ACCTG CWORK | C28: C010162 | D28: Global Accounting - Mobile Accounting | F28: L0001 | G28: U.S. Home Office | H28: Yes | I28: WS712
A29: 10273 | B29: 10273-HRO and FS Accounting | C29: C010163 | D29: Global Accounting - HRO and FS Accounting | F29: L0001 | G29: U.S. Home Office | H29: Yes | I29: 10273
A30: W20100 | B30: W20100-ESC Financial Reporting | C30: C010163 | D30: Global Accounting - HRO and FS Accounting | F30: L0001 | G30: U.S. Home Office | H30: Yes | I30: W20100
A31: 5020 | B31: 5020:TWG INFRASTRUCTURE | C31: C254011 | D31: GT - TWG Apps - Infrastructure | H31: Yes | I31: 5020
A32: 5021 | B32: 5021-Reporting | C32: C254018 | D32: GT - TWG Apps - Reporting | F32: L0001 | G32: U.S. Home Office | H32: Yes | I32: 5021
A33: 10274 | B33: 10274-Auto Accounting | C33: C010164 | D33: Global Accounting - Auto Accounting | F33: L0001 | G33: U.S. Home Office | H33: Yes | I33: 10274
A34: AA006 | B34: AA006-AFAS ACCOUNTING | C34: C010164 | D34: Global Accounting - Auto Accounting | F34: L0001 | G34: U.S. Home Office | H34: Yes | I34: AA006
A35: U9922 | B35: U9922-VPS ACCOUNTING | C35: C010164 | D35: Global Accounting - Auto Accounting | F35: L0001 | G35: U.S. Home Office | H35: Yes | I35: U9922
A36: WS400 | B36: WS400-Financial Operations | C36: C010165 | D36: Global Accounting - Mobile Financial Ops | F36: L0001 | G36: U.S. Home Office | H36: Yes | I36: WS400
A37: 10223 | B37: 10223-GLOW AND AIM PROJECT | C37: C010166 | D37: Global Accounting - GLOW and AIM Project | F37: L0001 | G37: U.S. Home Office | H37: Yes | I37: 10223
A38: 5022 | B38: 5022:WARRANTY LINK | C38: C254022 | D38: GT - TWG Apps - Warranty Link | H38: Yes | I38: 5022
A39: 5024 | B39: 5024:APAC LAM MANAGEMENT | C39: C254001 | D39: GT - TWG Apps - APAC LAM Mgt | H39: Yes | I39: 5024
A40: 5026 | B40: 5026:INTERNATIONAL PROJECTS | C40: C254012 | D40: GT - TWG Apps - International Projects | H40: Yes | I40: 5026
...

Sheet CC by Segment
A1: Cost Center Number | B1: Cost Center Details | C1: GFS CC | D1: Vlookup | E1: Segment
A2: 1013600 | B2: 1013600:SYRACUSE, NY FACILITY | C2: =VLOOKUP(A2,'Cost Center'!A:C,3,FALSE) -> #N/A | D2: C900000 | E2: Corporate | F2: 1013600
A3: 113048 | B3: 113048:CORPORATE MOBILITY | C3: =VLOOKUP(A3,'Cost Center'!A:C,3,FALSE) -> C200225 | D3: C200225 | E3: Corporate | F3: 113048
A4: 114005 | B4: 114005:PBP ENTERPRISE COO | C4: =VLOOKUP(A4,'Cost Center'!A:C,3,FALSE) -> C200509 | D4: C200509 | E4: Corporate | F4: 114005
A5: 39155 | B5: 39155:CORPORATE & SOCIAL RESPONSIBILITY | C5: =VLOOKUP(A5,'Cost Center'!A:C,3,FALSE) -> C200550 | D5: C200550 | E5: Corporate | F5: 39155
A6: 1013500 | B6: 1013500:WASHINGTON, DC FACILITY | C6: =VLOOKUP(A6,'Cost Center'!A:C,3,FALSE) -> C500517 | D6: C500517 | E6: Corporate | F6: 1013500
A7: 3200493 | B7: 3200493:WOODBURY MN FACILITY | C7: =VLOOKUP(A7,'Cost Center'!A:C,3,FALSE) -> C500518 | D7: C500518 | E7: Corporate | F7: 3200493
A8: 114300 | B8: 114300:NY OFFICE SERVICES | C8: =VLOOKUP(A8,'Cost Center'!A:C,3,FALSE) -> C500105 | D8: C500105 | E8: Corporate | F8: 114300
A9: 114450 | B9: 114450:INC NY CORPORATE FACILITY | C9: =VLOOKUP(A9,'Cost Center'!A:C,3,FALSE) -> C500519 | D9: C500519 | E9: Corporate | F9: 114450
A10: 8310310 | B10: 8310310:MFD AIZ | C10: =VLOOKUP(A10,'Cost Center'!A:C,3,FALSE) -> C200116 | D10: C200116 | E10: Corporate | F10: 8310310
A11: 114425 | B11: 114425:ATLANTA DATA CENTER | C11: =VLOOKUP(A11,'Cost Center'!A:C,3,FALSE) -> C500522 | D11: C500522 | E11: Corporate | F11: 114425
A12: 113035 | B12: 113035:PROCUREMENT OUTSOURCING | C12: =VLOOKUP(A12,'Cost Center'!A:C,3,FALSE) -> C200201 | D12: C200201 | E12: Corporate | F12: 113035
A13: 113041 | B13: 113041:VENDOR RISK & ANALYTICS | C13: =VLOOKUP(A13,'Cost Center'!A:C,3,FALSE) -> C200205 | D13: C200205 | E13: Corporate | F13: 113041
... A59: 113010 | B59: 113010:OFFICE OF CEO | C59: =VLOOKUP(A59,'Cost Center'!A:C,3,FALSE) -> C030101 | D59: C030101 | E59: Corporate | F59: 113010
A60: 304000 | B60: 0304000:ACTUARIAL PRENEED | C60: =VLOOKUP(A60,'Cost Center'!A:C,3,FALSE) -> #N/A | D60: #N/A | E60: Corporate | F60: 304000
A61: 113002 | B61: 113002:NETWORK OPERATIONS | C61: =VLOOKUP(A61,'Cost Center'!A:C,3,FALSE) -> C010902 | D61: C010902 | E61: Corporate | F61: 113002
A62: 150600 | B62: 150600:AAM MORTGAGES | C62: =VLOOKUP(A62,'Cost Center'!A:C,3,FALSE) -> #N/A | D62: C900000 | E62: Corporate | F62: 150600
A63: 150700 | B63: 150700:AAM EQUITY REAL ESTATE | C63: =VLOOKUP(A63,'Cost Center'!A:C,3,FALSE) -> C010702 | D63: C010702 | E63: Corporate | F63: 150700
A64: 150800 | B64: 150800:AAM FIXED INCOME | C64: =VLOOKUP(A64,'Cost Center'!A:C,3,FALSE) -> C010701 | D64: C010701 | E64: Corporate | F64: 150800
A65: 150950 | B65: 150950:AIM CORP | C65: =VLOOKUP(A65,'Cost Center'!A:C,3,FALSE) -> C010750 | D65: C010750 | E65: Corporate | F65: 150950
A66: 150952 | B66: 150952:AIM FUND | C66: =VLOOKUP(A66,'Cost Center'!A:C,3,FALSE) -> #N/A | D66: C900000 | E66: Corporate | F66: 150952
A67: 113049 | B67: 113049:Accounting & Finance Services - A&FS | C67: =VLOOKUP(A67,'Cost Center'!A:C,3,FALSE) -> C010121 | D67: C010121 | E67: Corporate | F67: 113049
A68: 113051 | B68: 113051:A&FS ONE TIME COSTS | C68: =VLOOKUP(A68,'Cost Center'!A:C,3,FALSE) -> C010123 | D68: C010123 | E68: Corporate | F68: 113051
A69: 113052 | B69: 113052:A&FS OPERATIONS | C69: =VLOOKUP(A69,'Cost Center'!A:C,3,FALSE) -> C010124 | D69: C010124 | E69: Corporate | F69: 113052
A70: 113053 | B70: 113053:A&FS CASH APPLICATIONS | C70: =VLOOKUP(A70,'Cost Center'!A:C,3,FALSE) -> C010122 | D70: C010122 | E70: Corporate | F70: 113053
A71: 113054 | B71: 113054:AFS RECON COE | C71: =VLOOKUP(A71,'Cost Center'!A:C,3,FALSE) -> C010127 | D71: C010127 | E71: Corporate | F71: 113054
A72: 113056 | B72: 113056:A&FS OUTSOURCING | C72: =VLOOKUP(A72,'Cost Center'!A:C,3,FALSE) -> C010126 | D72: C010126 | E72: Corporate | F72: 113056
... A87: 54320 | B87: 54320:ACTUARIAL DATA OPS & TECHNOLOGY | C87: =VLOOKUP(A87,'Cost Center'!A:C,3,FALSE) -> C010205 | D87: C010205 | E87: Corporate | F87: 54320
A88: U9913 | B88: U9913:ACTUARIAL GLOBAL AUTO | C88: =VLOOKUP(A88,'Cost Center'!A:C,3,FALSE) -> C010215 | D88: C010215 | E88: Corporate | F88: U9913
A89: 113020 | B89: 113020:CAPITAL AND FINANCIAL RATINGS | C89: =VLOOKUP(A89,'Cost Center'!A:C,3,FALSE) -> C010801 | D89: C010801 | E89: Corporate | F89: 113020
A90: 113240 | B90: 113240:TREASURY | C90: =VLOOKUP(A90,'Cost Center'!A:C,3,FALSE) -> C010800 | D90: C010800 | E90: Corporate | F90: 113240
A91: 150400 | B91: 150400:REVOLVER ISSUANCE COSTS | C91: =VLOOKUP(A91,'Cost Center'!A:C,3,FALSE) -> C010890 | D91: C010890 | E91: Corporate | F91: 150400
A92: 17202 | B92: 17202:TREASURY MANAGEMENT | C92: =VLOOKUP(A92,'Cost Center'!A:C,3,FALSE) -> C100601 | D92: C100601 | E92: Corporate | F92: 17202
A93: 122000 | B93: 122000:Global Risk Modeling and Insurance Purchasing | C93: =VLOOKUP(A93,'Cost Center'!A:C,3,FALSE) -> C010805 | D93: C010805 | E93: Corporate | F93: 122000
A94: 115003 | B94: 115003:RAS AEB | C94: =VLOOKUP(A94,'Cost Center'!A:C,3,FALSE) -> #N/A | D94: C900000 | E94: Corporate | F94: 115003
A95: 115027 | B95: 115027:RAS QA TRAINING | C95: =VLOOKUP(A95,'Cost Center'!A:C,3,FALSE) -> #N/A | D95: C900000 | E95: Corporate | F95: 115027
A96: 113040 | B96: 113040:OFFICE OF CFO | C96: =VLOOKUP(A96,'Cost Center'!A:C,3,FALSE) -> C010000 | D96: C010000 | E96: Corporate | F96: 113040
A97: 10300 | B97: 10300:MIAMI CORPORATE FP AND A | C97: =VLOOKUP(A97,'Cost Center'!A:C,3,FALSE) -> #N/A | D97: #N/A | E97: Corporate | F97: 10300
A98: 113100 | B98: 113100:CORPORATE FP AND A | C98: =VLOOKUP(A98,'Cost Center'!A:C,3,FALSE) -> C010410 | D98: C010410 | E98: Corporate | F98: 113100
A99: 113232 | B99: 113232:IT FINANCE EXECUTIVE | C99: =VLOOKUP(A99,'Cost Center'!A:C,3,FALSE) -> C010415 | D99: C010415 | E99: Corporate | F99: 113232
...

Sheet Email II
